Workbook

Sheet Índice
E9: Direcção das Contas Nacionais
C10: Departamento das Contas Nacionais
B11: Contas Nacionais Trimestras - 2002 - 2025
B13: Índice
B14: Q1 | C14: Quadro 1 - PIB Petrolífero e Não Petrolífero
B15: Q2 | C15: Quadro 2 - Medidas de Volume Encadeadas(com Ajuste Sazonal) em Milhões de Kwanzas
B16: Q3 | C16: Quadro 3 -Variação % Trimestre por Trimestre ( Ajustado Sazonalmente)
B17: Q4 | C17: Quadro 4 - Contribuição % das Actividades Económicas na Taxa de Crescimento do PIB Trimestral Ajustado Sazonalmente
B18: Q5 | C18: Quadro 5 - PIB_Trimestral_Medidas de Volume Encadeadas (Não Ajustada) em Milhões de Kwanzas
B19: Q6 | C19: Quadro 6 - PIB_Trimestral_Medidas de Volume Encadeadas (Não Ajustada) - Variação Homóloga %
B20: Q7 | C20: Quadro 7 - Contribuição % das Actividades Económicas na Taxa de Crescimento do PIB Trimestral - Medidas de Volume Encadeadas (Não Ajustada)
B21: Q8 | C21: Quadro 8 - PIB Ttrimestral Valor de Medida_Encadeada Acumulada ao Longo do Ano em Milhões de Kwanzas
B22: Q9 | C22: Quadro 9 - Variação % Acumulada ao Longo do Ano
B23: Q10 | C23: Quadro 10 - PIB Trimestral- Valor de Medida Encadeada Acumulada nos Últimos 4 Trimestres em Milhões de Kwanzas
B24: Q11 | C24: Quadro 11 - Variação % Acumulada nos Últimos 4 Trimestres
B25: Q12 | C25: Quadro 12 - PIB em Milhões de Kwanzas a Preços Correntes
... B28: Q15 | C28: Quadro 15 - PIB por sector de actividades

Sheet Q1
C1: Quadro 1 - PIB Petrolífero e Não Petrolífero
D2: Em Milhões de Kwanzas | G2: Participação % | J2: Variação Homóloga % | M2: Contribuição %
B3: Período | D3: PIB Petroliféro (Extracção e Refino de Petróleo ) | E3: PIB NÃO PETROLIFÉRO | F3: PRODUCTO INTERNO BRUTO | G3: PIB Petroliféro (Extracção e Refino de Petróleo ) | H3: PIB NÃO PETROLIFÉRO | I3: PRODUCTO INTERNO BRUTO | J3: PIB Petroliféro (Extracção e Refino de Petróleo ) | K3: PIB NÃO PETROLIFÉRO | L3: PRODUCTO INTERNO BRUTO | M3: PIB Petroliféro (Extracção e Refino de Petróleo ) | N3: PIB NÃO PETROLIFÉRO | O3: PRODUCTO INTERNO BRUTO
B4: 2002 | C4: Total | D4: 295071.18 | E4: 458502.54 | F4: 753573.72 | G4: 39.156246 | H4: 60.843754 | I4: =+G4+H4 -> 100 | J4: 0 | L4: 0
B5: 2002 | C5: I TRIM | D5: 50703.677 | E5: 79602.785 | F5: 130306.46 | G5: 38.9111 | H5: 61.0889 | I5: =+G5+H5 -> 100 | J5: 0 | L5: 0
C6: II TRIM | D6: 66093.908 | E6: 100524.83 | F6: 166618.74 | G6: 39.667752 | H6: 60.332248 | I6: =+G6+H6 -> 100 | J6: 0 | L6: 0
C7: III TRIM | D7: 83830.978 | E7: 120347.54 | F7: 204178.51 | G7: 41.057689 | H7: 58.942311 | I7: =+G7+H7 -> 100 | J7: 0 | L7: 0
C8: IV TRIM | D8: 94442.62 | E8: 158027.39 | F8: 252470.01 | G8: 37.407461 | H8: 62.592539 | I8: =+G8+H8 -> 100 | J8: 0 | L8: 0
B9: 2003 | C9: Total | D9: 541281.93 | E9: 976369 | F9: 1517650.9 | G9: 35.665773 | H9: 64.334227 | I9: =+G9+H9 -> 100 | J9: -3.8749525 | K9: 8.2253281 | L9: 3.4873124 | M9: -1.5172859 | N9: 5.0045983 | O9: 3.4873124
B10: 2003 | C10: I TRIM | D10: 129469.82 | E10: 166831.59 | F10: 296301.42 | G10: 43.69531 | H10: 56.30469 | I10: =+G10+H10 -> 100 | J10: -4.0007568 | K10: 3.9210219 | L10: 0.81915072 | M10: -1.5665462 | N10: 2.3856969 | O10: 0.81915072
C11: II TRIM | D11: 124948.97 | E11: 232237.15 | F11: 357186.12 | G11: 34.981474 | H11: 65.018526 | I11: =+G11+H11 -> 100 | J11: -4.1256314 | K11: 9.9743297 | L11: 4.4533142 | M11: -1.6154424 | N11: 6.0687566 | O11: 4.4533142
C12: III TRIM | D12: 149175.34 | E12: 268783.5 | F12: 417958.84 | G12: 35.691396 | H12: 64.308604 | I12: =+G12+H12 -> 100 | J12: -4.0190518 | K12: 11.158899 | L12: 5.2157831 | M12: -1.5737098 | N12: 6.7894929 | O12: 5.2157831
C13: IV TRIM | D13: 137687.8 | E13: 308516.76 | F13: 446204.56 | G13: 30.85755 | H13: 69.14245 | I13: =+G13+H13 -> 100 | J13: -3.3574444 | K13: 7.8078614 | L13: 3.4359468 | M13: -1.3146492 | N13: 4.750596 | O13: 3.4359468
B14: 2004 | C14: Total | D14: 821202.14 | E14: 1434245.7 | F14: 2255447.9 | G14: 36.409715 | H14: 63.590285 | I14: =+G14+H14 -> 100 | J14: 13.755586 | K14: 10.12498 | L14: 11.419863 | M14: 4.906036 | N14: 6.5138274 | O14: 11.419863
B15: 2003 | C15: I TRIM | D15: 172541.71 | E15: 244074.08 | F15: 416615.79 | G15: 41.415068 | H15: 58.584932 | I15: =+G15+H15 -> 100 | J15: 12.669737 | K15: -6.1985197 | L15: 0.53098981 | M15: 4.5187595 | N15: -3.9877697 | O15: 0.53098981
C16: II TRIM | D16: 179895.27 | E16: 373933.97 | F16: 553829.23 | G16: 32.482082 | H16: 67.517918 | I16: =+G16+H16 -> 100 | J16: 13.932515 | K16: 19.603222 | L16: 17.58072 | M16: 4.969139 | N16: 12.611581 | O16: 17.58072
C17: III TRIM | D17: 223187.57 | E17: 384844.86 | F17: 608032.42 | G17: 36.706524 | H17: 63.293476 | I17: =+G17+H17 -> 100 | J17: 14.30167 | K17: 13.247868 | L17: 13.623714 | M17: 5.100801 | N17: 8.5229133 | O17: 13.623714
C18: IV TRIM | D18: 245577.59 | E18: 431392.83 | F18: 676970.42 | G18: 36.275971 | H18: 63.724029 | I18: =+G18+H18 -> 100 | J18: 14.143116 | K18: 12.815444 | L18: 13.288968 | M18: 5.0442516 | N18: 8.2447167 | O18: 13.288968
B19: 2005 | C19: Total | D19: 1560680.6 | E19: 2047414.7 | F19: 3608095.3 | G19: 43.254972 | H19: 56.745028 | I19: =+G19+H19 -> 100 | J19: 25.256772 | K19: 7.7981389 | L19: 14.154778 | M19: 9.1959188 | N19: 4.9588587 | O19: 14.154778
B20: 2003 | C20: I TRIM | D20: 351197.92 | E20: 461184.9 | F20: 812382.82 | G20: 43.230594 | H20: 56.769406 | I20: =+G20+H20 -> 100 | J20: 26.642065 | K20: 46.211285 | L20: 39.086188 | M20: 9.7002998 | N20: 29.385888 | O20: 39.086188
C21: II TRIM | D21: 357911.73 | E21: 526306.93 | F21: 884218.66 | G21: 40.47774 | H21: 59.52226 | I21: =+G21+H21 -> 100 | J21: 26.380336 | K21: 8.2424794 | L21: 14.846421 | M21: 9.6050053 | N21: 5.2414162 | O21: 14.846421
C22: III TRIM | D22: 461027.64 | E22: 538863.93 | F22: 999891.57 | G22: 46.107763 | H22: 53.892237 | I22: =+G22+H22 -> 100 | J22: 25.062703 | K22: 6.666227 | L22: 13.364332 | M22: 9.1252589 | N22: 4.2390728 | O22: 13.364332
C23: IV TRIM | D23: 390543.33 | E23: 521058.92 | F23: 911602.25 | G23: 42.841418 | H23: 57.158582 | I23: =+G23+H23 -> 100 | J23: 22.978415 | K23: -20.113813 | L23: -4.4240556 | M23: 8.3663753 | N23: -12.790431 | O23: -4.4240556
B24: 2006 | C24: Total | D24: 1904860.2 | E24: 2809021.4 | F24: 4713881.6 | G24: 40.40959 | H24: 59.59041 | I24: =+G24+H24 -> 100 | J24: 12.969347 | K24: 10.982338 | L24: 11.841818 | M24: 5.6098873 | N24: 6.2319305 | O24: 11.841818
B25: 2003 | C25: I TRIM | D25: 476232.51 | E25: 639079.86 | F25: 1115312.4 | G25: 42.699473 | H25: 57.300527 | I25: =+G25+H25 -> 100 | J25: 12.401153 | K25: 3.3304829 | L25: 7.2539986 | M25: 5.3641152 | N25: 1.8898835 | O25: 7.2539986
C26: II TRIM | D26: 500115.25 | E26: 715220.88 | F26: 1215336.1 | G26: 41.150365 | H26: 58.849635 | I26: =+G26+H26 -> 100 | J26: 11.557789 | K26: 4.1147072 | L26: 7.3342102 | M26: 4.9993185 | N26: 2.3348917 | O26: 7.3342102
C27: III TRIM | D27: 495177.77 | E27: 694518.82 | F27: 1189696.6 | G27: 41.62219 | H27: 58.37781 | I27: =+G27+H27 -> 100 | J27: 13.271641 | K27: 4.66276 | L27: 8.386529 | M27: 5.7406446 | N27: 2.6458845 | O27: 8.386529
C28: IV TRIM | D28: 433334.67 | E28: 760201.81 | F28: 1193536.5 | G28: 36.306781 | H28: 63.693219 | I28: =+G28+H28 -> 100 | J28: 14.646852 | K28: 33.629059 | L28: 25.41831 | M28: 6.3354917 | N28: 19.082819 | O28: 25.41831
B29: 2007 | C29: Total | D29: 2436848.8 | E29: 3165600.8 | F29: 5602449.6 | G29: 43.496131 | H29: 56.503869 | I29: =+G29+H29 -> 100 | J29: 21.652374 | K29: 7.137144 | L29: 13.002689 | M29: 8.7496355 | N29: 4.2530534 | O29: 13.002689
B30: 2003 | C30: I TRIM | D30: 541387.35 | E30: 720031.72 | F30: 1261419.1 | G30: 42.918913 | H30: 57.081087 | I30: =+G30+H30 -> 100 | J30: 21.880697 | K30: 8.8242912 | L30: 14.100331 | M30: 8.8419 | N30: 5.2584313 | O30: 14.100331
C31: II TRIM | D31: 533719.66 | E31: 794964.1 | F31: 1328683.8 | G31: 40.169051 | H31: 59.830949 | I31: =+G31+H31 -> 100 | J31: 22.105552 | K31: 8.0997152 | L31: 13.759416 | M31: 8.9327629 | N31: 4.8266535 | O31: 13.759416
C32: III TRIM | D32: 624830.23 | E32: 846321.93 | F32: 1471152.2 | G32: 42.472169 | H32: 57.527831 | I32: =+G32+H32 -> 100 | J32: 21.078131 | K32: 11.42461 | L32: 15.325558 | M32: 8.5175862 | N32: 6.807972 | O32: 15.325558
C33: IV TRIM | D33: 736911.6 | E33: 804283.02 | F33: 1541194.6 | G33: 47.814312 | H33: 52.185688 | I33: =+G33+H33 -> 100 | J33: 21.56124 | K33: 0.6913588 | L33: 9.1247923 | M33: 8.7128088 | N33: 0.41198355 | O33: 9.1247923
B34: 2008 | C34: Total | D34: 3231741.1 | E34: 4180836.4 | F34: 7412577.5 | G34: 43.598075 | H34: 56.401925 | I34: =+G34+H34 -> 100 | J34: 10.171587 | K34: 11.260095 | L34: 10.786636 | M34: 4.4242468 | N34: 6.3623893 | O34: 10.786636
B35: 2003 | C35: I TRIM | D35: 871927.81 | E35: 915628.42 | F35: 1787556.2 | G35: 48.777644 | H35: 51.222356 | I35: =+G35+H35 -> 100 | J35: 10.551784 | K35: 9.0646644 | L35: 9.7115038 | M35: 4.5896177 | N35: 5.1218861 | O35: 9.7115038
C36: II TRIM | D36: 1050516.7 | E36: 1004836.9 | F36: 2055353.6 | G36: 51.111238 | H36: 48.888762 | I36: =+G36+H36 -> 100 | J36: 10.914059 | K36: 2.6086871 | L36: 6.2212027 | M36: 4.7471936 | N36: 1.4740091 | O36: 6.2212027
C37: III TRIM | D37: 906829.11 | E37: 1059365.8 | F37: 1966194.9 | G37: 46.121018 | H37: 53.878982 | I37: =+G37+H37 -> 100 | J37: 10.070843 | K37: 4.7941024 | L37: 7.0892803 | M37: 4.380427 | N37: 2.7088533 | O37: 7.0892803
C38: IV TRIM | D38: 402467.54 | E38: 1201005.3 | F38: 1603472.8 | G38: 25.099742 | H38: 74.900258 | I38: =+G38+H38 -> 100 | J38: 9.1676382 | K38: 28.085846 | L38: 19.857157 | M38: 3.987568 | N38: 15.86959 | O38: 19.857157
B39: 2009 | C39: Total | D39: 1536797.1 | E39: 4944724.7 | F39: 6481521.8 | G39: 23.710436 | H39: 76.289564 | I39: =+G39+H39 -> 100 | J39: -6.2164049 | K39: 8.3433712 | L39: 1.9955891 | M39: -2.7102329 | N39: 4.705822 | O39: 1.9955891
B40: 2003 | C40: I TRIM | D40: 281768.2 | E40: 1149418.2 | F40: 1431186.4 | G40: 19.687736 | H40: 80.312264 | I40: =+G40+H40 -> 100 | J40: -7.3165217 | K40: 8.1994052 | L40: 1.4347597 | M40: -3.1898626 | N40: 4.6246224 | O40: 1.4347597
...

Sheet Q2
C1: Quadro 2 - Medidas de Volume Encadeadas(com Ajuste Sazonal) em Milhões de Kwanzas
B2: Período | D2: Agro-Pecuária e Silvicultura | E2: Pesca e Aquicultura | F2: Extracção e Refino de Petróleo | G2: Extracção de Diamantes, Minerais Metálicos e de Outros Minerais não Metálicos | H2: Produtos da Indústria Transformadora | I2: Produção de Electricidade, Água e Saneamento | J2: Construção | K2: Comércio e Raparação de Veiculos | L2: Serviço de Alojamento e Restauração | M2: Transportes e Armazenagem | N2: Actividades de informação e de comunicação | O2: Intermediação Financeira e de Seguros | P2: Administração Pública, Defesa e Segurança Social Obrigatória | Q2: Serviços Imobiliários e Aluguer | R2: Outros Serviços | S2: Imposto sobre os produtos | T2: Subsídios (-) | U2: PRODUCTO INTERNO BRUTO
B3: 2002 | C3: I TRIM | D3: 198659.46 | E3: 19249.05 | F3: 317550.06 | G3: 12771.318 | H3: 86070.548 | I3: 11169.378 | J3: 132954.36 | K3: 164848.98 | L3: 37220.871 | M3: 73600.344 | N3: 21183.762 | O3: 28349.376 | P3: 183197.47 | Q3: 68452.273 | R3: 84785.152 | S3: 45536.408 | T3: -16118.798 | U3: 1521100.2
C4: II TRIM | D4: 199296.23 | E4: 19712.953 | F4: 302058.3 | G4: 11663.619 | H4: 85196.518 | I4: 11910.01 | J4: 134623.22 | K4: 182167.95 | L4: 33349.833 | M4: 73496.351 | N4: 21362.352 | O4: 30889.772 | P4: 194161.38 | Q4: 72003.427 | R4: 89482.096 | S4: 49890.561 | T4: -18218.301 | U4: 1552830.4
C5: III TRIM | D5: 201708.94 | E5: 19989.561 | F5: 312003.28 | G5: 14470.689 | H5: 85445.263 | I5: 13035.15 | J5: 137655.41 | K5: 203860.47 | L5: 31658.495 | M5: 72981.114 | N5: 21479.211 | O5: 40614.693 | P5: 200323.99 | Q5: 74893.458 | R5: 98415.164 | S5: 55341.372 | T5: -20810.12 | U5: 1623993
C6: IV TRIM | D6: 204558.43 | E6: 18931.125 | F6: 310387.97 | G6: 13848.169 | H6: 86872.041 | I6: 12364.386 | J6: 142008.55 | K6: 233148.63 | L6: 30600.512 | M6: 72336.05 | N6: 21632.218 | O6: 47578.133 | P6: 218788.16 | Q6: 86237.551 | R6: 112824.83 | S6: 71518.252 | T6: -26688.71 | U6: 1724172.6
B7: 2003 | C7: I TRIM | D7: 211597.23 | E7: 20305.874 | F7: 304845.65 | G7: 12647.069 | H7: 89177.105 | I7: 13909.063 | J7: 147301.57 | K7: 179278.82 | L7: 38459.252 | M7: 73513.89 | N7: 22073.309 | O7: 27534.652 | P7: 200802.36 | Q7: 65051.793 | R7: 87165.925 | S7: 55168.09 | T7: -19054.368 | U7: 1532512.8
C8: II TRIM | D8: 216267.63 | E8: 20976.239 | F8: 289596.49 | G8: 15184.672 | H8: 89696.012 | I8: 13957.943 | J8: 154489.79 | K8: 205566.63 | L8: 36424.399 | M8: 73720.324 | N8: 22464.69 | O8: 33242.507 | P8: 214203.9 | Q8: 73343.738 | R8: 94541.016 | S8: 59261.368 | T8: -18735.933 | U8: 1620315.7
C9: III TRIM | D9: 220945.34 | E9: 21375.117 | F9: 299463.71 | G9: 19181.876 | H9: 91397.42 | I9: 12876.312 | J9: 162985.09 | K9: 220427.92 | L9: 36529.163 | M9: 73605.087 | N9: 22631.436 | O9: 44932.474 | P9: 218155.28 | Q9: 83844.741 | R9: 102588.79 | S9: 63199.018 | T9: -18308.962 | U9: 1709730.9
C10: IV TRIM | D10: 226198.71 | E10: 21060.934 | F10: 299966.87 | G10: 16188.743 | H10: 94674.331 | I10: 13489.262 | J10: 172833.86 | K10: 231606.62 | L10: 37869.957 | M10: 74110.729 | N10: 22589.625 | O10: 50617.162 | P10: 228165.24 | Q10: 89041.277 | R10: 111211.99 | S10: 75582.27 | T10: -20388.983 | U10: 1787247.3
B11: 2004 | C11: I TRIM | D11: 233500.86 | E11: 22030.038 | F11: 343468.79 | G11: 15656.92 | H11: 103671.39 | I11: 14046.099 | J11: 183734.49 | K11: 213575.26 | L11: 42587.071 | M11: 76624.575 | N11: 22447.149 | O11: 33911.205 | P11: 234888.2 | Q11: 82559.679 | R11: 106228.89 | S11: 57441.614 | T11: -81742.836 | U11: 1537464.4
C12: II TRIM | D12: 237482.3 | E12: 22458.919 | F12: 329944.57 | G12: 16431.813 | H12: 108790.28 | I12: 15478.218 | J12: 193833.28 | K12: 221244.82 | L12: 44753.435 | M12: 78258.038 | N12: 22932.277 | O12: 31584.591 | P12: 228738.59 | Q12: 82123.303 | R12: 110972.41 | S12: 65479.848 | T12: -1154.8423 | U12: 1903049.4
C13: III TRIM | D13: 241211.56 | E13: 22662.984 | F13: 342292.02 | G13: 18049.641 | H13: 112251.21 | I13: 16763.473 | J13: 202669.12 | K13: 224970.2 | L13: 45677.62 | M13: 79527.118 | N13: 23714.766 | O13: 43926.245 | P13: 251425.99 | Q13: 77075.967 | R13: 113133.61 | S13: 56429.131 | T13: -1186.5571 | U13: 1942316.4
C14: IV TRIM | D14: 245781.89 | E14: 21842.576 | F14: 342391.53 | G14: 17793.462 | H14: 112676.35 | I14: 15573.659 | J14: 209851.77 | K14: 233966.47 | L14: 44260.319 | M14: 81156.554 | N14: 23830.921 | O14: 52159.246 | P14: 238706.73 | Q14: 76885.399 | R14: 116559.5 | S14: 84545.204 | T14: -1290.5463 | U14: 2034518.5
B15: 2005 | C15: I TRIM | D15: 243495.63 | E15: 22299.293 | F15: 434975.97 | G15: 13654.908 | H15: 114948 | I15: 16118.247 | J15: 215154.47 | K15: 243610.66 | L15: 44526.582 | M15: 83855.208 | N15: 21810.394 | O15: 33944.593 | P15: 275165.61 | Q15: 84202.569 | R15: 116195.85 | S15: 67792.692 | T15: -2288.4876 | U15: 2130432.5
C16: II TRIM | D16: 245686.99 | E16: 22959.059 | F16: 416985.05 | G16: 14973.456 | H16: 117217.82 | I16: 16026.161 | J16: 220649.81 | K16: 246876.63 | L16: 41880.904 | M16: 86175.108 | N16: 19181.038 | O16: 41507.005 | P16: 266843.31 | Q16: 84683.125 | R16: 116694.03 | S16: 68875.287 | T16: -2432.1554 | U16: 2183279.6
C17: III TRIM | D17: 251714.68 | E17: 23902.196 | F17: 428079.65 | G17: 15204.26 | H17: 119346.45 | I17: 16415.916 | J17: 225937.81 | K17: 247643.13 | L17: 39817.199 | M17: 87857.906 | N17: 17209.36 | O17: 53333.354 | P17: 256302.66 | Q17: 82651.007 | R17: 119360.07 | S17: 65696.63 | T17: -2382.1298 | U17: 2200469.3
C18: IV TRIM | D18: 262424.32 | E18: 24164.416 | F18: 421067.67 | G18: 12839.608 | H18: 120608.8 | I18: 17946.074 | J18: 230978.7 | K18: 249662.93 | L18: 40122.846 | M18: 89110.808 | N18: 16771.563 | O18: 66325.45 | P18: 274326.04 | Q18: 82569.142 | R18: 125507.48 | S18: 89659.644 | T18: -84375.011 | U18: 1955859.1
B19: 2006 | C19: I TRIM | D19: 272824.75 | E19: 26668.831 | F19: 488918 | G19: 17477.84 | H19: 124316.12 | I19: 19119.297 | J19: 235655.72 | K19: 258371.35 | L19: 48919.256 | M19: 90847.573 | N19: 18671.758 | O19: 37136.016 | P19: 284833.08 | Q19: 86725.838 | R19: 135520.2 | S19: 62022.121 | T19: -19622.933 | U19: 2274791.4
C20: II TRIM | D20: 281344.98 | E20: 27947.398 | F20: 465179.31 | G20: 16971.207 | H20: 126963.58 | I20: 19009.201 | J20: 242767.42 | K20: 253985.04 | L20: 51536.178 | M20: 92669.42 | N20: 20404.309 | O20: 40590.493 | P20: 326409.36 | Q20: 87359.872 | R20: 139224 | S20: 67189.653 | T20: -20646.574 | U20: 2343268.7
C21: III TRIM | D21: 287662.24 | E21: 29029.914 | F21: 484892.85 | G21: 19513.612 | H21: 128944.48 | I21: 19863.882 | J21: 251755.32 | K21: 255267.04 | L21: 54529.707 | M21: 93452.888 | N21: 21600.938 | O21: 61039.736 | P21: 266119.82 | Q21: 86151.423 | R21: 138093.22 | S21: 77578.538 | T21: -22223.698 | U21: 2380695.8
C22: IV TRIM | D22: 293525.27 | E22: 30532.394 | F22: 482740.83 | G22: 18901.569 | H22: 130202.98 | I22: 22491.355 | J22: 262764.28 | K22: 261616.53 | L22: 55979.389 | M22: 94028.546 | N22: 21962.19 | O22: 89833.516 | P22: 319627.05 | Q22: 94469.85 | R22: 132993.3 | S22: 103868.52 | T22: -39443.749 | U22: 2465679.1
B23: 2007 | C23: I TRIM | D23: 294182.69 | E23: 30347.98 | F23: 595896.67 | G23: 19612.769 | H23: 130707.85 | I23: 12623.682 | J23: 275517.5 | K23: 277384.34 | L23: 56392.958 | M23: 95937.662 | N23: 21566.195 | O23: 47125.503 | P23: 337448.26 | Q23: 92676.873 | R23: 126870.55 | S23: 89191.673 | T23: -27987.468 | U23: 2590575.3
C24: II TRIM | D24: 295700.72 | E24: 30222.356 | F24: 568009.76 | G24: 16649.152 | H24: 131469.38 | I24: 24845.651 | J24: 287123.13 | K24: 283402.11 | L24: 58421.917 | M24: 98393.842 | N24: 21760.401 | O24: 51617.035 | P24: 340365.55 | Q24: 92940.942 | R24: 119679.35 | S24: 86699.158 | T24: -14516.278 | U24: 2661769.4
C25: III TRIM | D25: 298840.36 | E25: 30474.119 | F25: 587099.2 | G25: 22248.515 | H25: 132539.76 | I25: 25261.45 | J25: 297233.06 | K25: 293324.82 | L25: 59086.583 | M25: 101197.93 | N25: 22669.883 | O25: 65753.505 | P25: 338189.74 | Q25: 92688.784 | R25: 116296.65 | S25: 90215.897 | T25: -1526.1286 | U25: 2739700.4
C26: IV TRIM | D26: 304999.43 | E26: 30590.298 | F26: 586825.74 | G26: 28275.851 | H26: 134703.82 | I26: 24823.871 | J26: 305575.62 | K26: 305849.83 | L26: 58956.02 | M26: 106169.07 | N26: 24471.415 | O26: 76843.567 | P26: 314257.19 | Q26: 93613.203 | R26: 118461.88 | S26: 87290.982 | T26: -66041.647 | U26: 2703358.4
B27: 2008 | C27: I TRIM | D27: 310654.78 | E27: 30506.099 | F27: 658774.4 | G27: 22384.442 | H27: 136104.57 | I27: 25007.009 | J27: 311689.95 | K27: 324497.92 | L27: 61394.781 | M27: 112957.48 | N27: 27444.182 | O27: 43600.991 | P27: 298012.96 | Q27: 99384.178 | R27: 124069.68 | S27: 81032.798 | T27: -21452.415 | U27: 2839647.5
C28: II TRIM | D28: 314302.07 | E28: 30785.409 | F28: 630002.68 | G28: 23601.017 | H28: 136470.91 | I28: 20266.546 | J28: 316732.06 | K28: 335100.39 | L28: 63393.172 | M28: 118529.78 | N28: 30246.94 | O28: 47283.246 | P28: 327506.51 | Q28: 101137.24 | R28: 125914.08 | S28: 106415.17 | T28: -44630.148 | U28: 2825708.8
C29: III TRIM | D29: 317754.86 | E29: 31417.966 | F29: 646225.03 | G29: 23816.482 | H29: 137082.78 | I29: 25455.501 | J29: 320636.56 | K29: 345426.32 | L29: 64511.141 | M29: 122727.29 | N29: 32641.953 | O29: 67425.599 | P29: 369671.27 | Q29: 103284.81 | R29: 127796.69 | S29: 113887.52 | T29: -35820.413 | U29: 2920705.6
C30: IV TRIM | D30: 322595.84 | E30: 31609.621 | F30: 640623.8 | G30: 15351.173 | H30: 140517.63 | I30: 25337.907 | J30: 323691.91 | K30: 352682.14 | L30: 65596.98 | M30: 124025.65 | N30: 34521.415 | O30: 108071.64 | P30: 392310.12 | Q30: 106690.29 | R30: 129408.28 | S30: 111039.92 | T30: -6539.4877 | U30: 3256619.7
B31: 2009 | C31: I TRIM | D31: 325130.07 | E31: 32664.851 | F31: 610575.03 | G31: 17293.647 | H31: 146006.52 | I31: 22023.002 | J31: 325552.42 | K31: 357054.92 | L31: 67816.08 | M31: 122546.35 | N31: 36191.598 | O31: 63299.244 | P31: 393401.23 | Q31: 100084.89 | R31: 130539.5 | S31: 114232.48 | T31: -8102.1084 | U31: 2885049
C32: II TRIM | D32: 328369.52 | E32: 33337.368 | F32: 589657.2 | G32: 25973.425 | H32: 149073.9 | I32: 26513.967 | J32: 331235.93 | K32: 362438.63 | L32: 71615.22 | M32: 123235.84 | N32: 37824.448 | O32: 60974.852 | P32: 410820.56 | Q32: 110851.15 | R32: 131057.33 | S32: 91350.109 | T32: -15577.615 | U32: 3002895.3
C33: III TRIM | D33: 335236.56 | E33: 33827.082 | F33: 608868.98 | G33: 23724.984 | H33: 152441.91 | I33: 26364.092 | J33: 339682.74 | K33: 369163.08 | L33: 73792.943 | M33: 124403.91 | N33: 38756.667 | O33: 85823.959 | P33: 384793.28 | Q33: 114666.93 | R33: 133019.84 | S33: 106892.42 | T33: -14821.291 | U33: 3049818.3
C34: IV TRIM | D34: 347119.17 | E34: 33243.036 | F34: 606413.38 | G34: 21832.485 | H34: 154886.69 | I34: 26891.276 | J34: 351452.37 | K34: 375445.88 | L34: 75744.958 | M34: 128013.71 | N34: 38346.575 | O34: 70180.034 | P34: 441609.17 | Q34: 116394.27 | R34: 136841.94 | S34: 99900.403 | T34: -69941.45 | U34: 3145917.3
B35: 2010 | C35: I TRIM | D35: 359869.46 | E35: 32924.6 | F35: 618953.64 | G35: 21757.964 | H35: 158065.41 | I35: 27320.046 | J35: 365610.84 | K35: 381128.31 | L35: 74606.071 | M35: 130896.51 | N35: 36563.604 | O35: 53916.544 | P35: 422212.5 | Q35: 114977.48 | R35: 140228.51 | S35: 82672.158 | T35: -1638.051 | U35: 3118660.1
C36: II TRIM | D36: 369138.52 | E36: 33386.065 | F36: 600419.36 | G36: 19788.766 | H36: 162623.65 | I36: 25855.097 | J36: 376996.77 | K36: 390491.13 | L36: 79854.809 | M36: 133984.09 | N36: 36709.805 | O36: 62210.359 | P36: 458326.12 | Q36: 116971.79 | R36: 144919.33 | S36: 99101.936 | T36: -5522.0699 | U36: 3305885.8
C37: III TRIM | D37: 377208.63 | E37: 34387.539 | F37: 594711.12 | G37: 20993.895 | H37: 166843.27 | I37: 28198.798 | J37: 384989.96 | K37: 402549.91 | L37: 82540.748 | M37: 137642.88 | N37: 39855.275 | O37: 73608.727 | P37: 426278.19 | Q37: 118224.68 | R37: 149954.67 | S37: 126983.42 | T37: -3272.7913 | U37: 3296291.5
C38: IV TRIM | D38: 385906.85 | E38: 33977.297 | F38: 545514.94 | G38: 19932.129 | H38: 169826.28 | I38: 30498.6 | J38: 389611.05 | K38: 414240.56 | L38: 85099.1 | M38: 143918.14 | N38: 47328.845 | O38: 97105.936 | P38: 387082.02 | Q38: 118627.1 | R38: 155033.16 | S38: 130547.3 | T38: -121221.81 | U38: 2995404.7
B39: 2011 | C39: I TRIM | D39: 390575.77 | E39: 36398.955 | F39: 560235.21 | G39: 19937.825 | H39: 174446.3 | I39: 29458.032 | J39: 390375.22 | K39: 420617.94 | L39: 80809.722 | M39: 143558.32 | N39: 59760.868 | O39: 63515.775 | P39: 421820.95 | Q39: 119061.96 | R39: 156214.84 | S39: 97256.78 | T39: -2040.6233 | U39: 3189716.8
C40: II TRIM | D40: 393911.4 | E40: 37988.252 | F40: 507017.01 | G40: 24104.985 | H40: 178709.85 | I40: 29589.264 | J40: 399920.39 | K40: 429615.57 | L40: 86782.536 | M40: 145264.14 | N40: 70908.019 | O40: 54345.106 | P40: 410544.2 | Q40: 119949.64 | R40: 160073.52 | S40: 110094.14 | T40: -1956.0763 | U40: 3218031.8
...

Sheet Q3
C1: Quadro 3 -Variação % Trimestre por Trimestre ( Ajustado Sazonalmente)
B2: Período | D2: Agro-Pecuária e Silvicultura | E2: Pesca e Aquicultura | F2: Extracção e Refino de Petróleo | G2: Extracção de Diamantes, Minerais Metálicos e de Outros Minerais não Metálicos | H2: Produtos da Indústria Transformadora | I2: Produção de Electricidade, Água e Saneamento | J2: Construção | K2: Comércio e Raparação de Veiculos | L2: Serviço de Alojamento e Restauração | M2: Transportes e Armazenagem | N2: Actividades de informação e de comunicação | O2: Intermediação Financeira e de Seguros | P2: Administração Pública, Defesa e Segurança Social Obrigatória | Q2: Serviços Imobiliários e Aluguer | R2: Outros Serviços | S2: Imposto sobre os produtos | T2: Subsídios (-) | U2: PRODUCTO INTERNO BRUTO
B3: 2002 | C3: I TRIM | D3: 0 | E3: 0 | F3: 0 | G3: 0 | H3: 0 | I3: 0 | J3: 0 | K3: 0 | L3: 0 | M3: 0 | N3: 0 | O3: 0 | P3: 0 | Q3: 0 | R3: 0 | S3: 0 | T3: 0 | U3: 0
C4: II TRIM | D4: 0.32053255 | E4: 2.4100053 | F4: -4.878523 | G4: -8.6733329 | H4: -1.0154808 | I4: 6.6309155 | J4: 1.2552068 | K4: 10.505963 | L4: -10.400183 | M4: -0.14129345 | N4: 0.84304964 | O4: 8.9610298 | P4: 5.9847477 | Q4: 5.18778 | R4: 5.5398193 | S4: 9.5619171 | T4: 13.025186 | U4: 2.0860017
C5: III TRIM | D5: 1.2106171 | E5: 1.4031789 | F5: 3.292404 | G5: 24.066886 | H5: 0.29196608 | I5: 9.4470048 | J5: 2.2523589 | K5: 11.907979 | L5: -5.0715026 | M5: -0.70103773 | N5: 0.54703431 | O5: 31.48266 | P5: 3.1739668 | Q5: 4.0137411 | R5: 9.983079 | S5: 10.925534 | T5: 14.226458 | U5: 4.5827706
C6: IV TRIM | D6: 1.4126722 | E6: -5.2949451 | F6: -0.51772333 | G6: -4.3019383 | H6: 1.6698149 | I6: -5.1458094 | J6: 3.162339 | K6: 14.366767 | L6: -3.3418602 | M6: -0.88387887 | N6: 0.71235031 | O6: 17.145123 | P6: 9.2171497 | Q6: 15.146975 | R6: 14.641715 | S6: 29.231079 | T6: 28.248704 | U6: 6.1687182
B7: 2003 | C7: I TRIM | D7: 3.4409731 | E7: 7.2618463 | F7: -1.78561 | G7: -8.6733434 | H7: 2.6534021 | I7: 12.492955 | J7: 3.7272596 | K7: -23.105352 | L7: 25.681727 | M7: 1.6282898 | N7: 2.0390451 | O7: -42.127505 | P7: -8.2206433 | Q7: -24.566744 | R7: -22.742251 | S7: -22.861523 | T7: -28.605138 | U7: -11.116042
C8: II TRIM | D8: 2.2072124 | E8: 3.3013332 | F8: -5.0022558 | G8: 20.064746 | H8: 0.5818838 | I8: 0.35142641 | J8: 4.8799314 | K8: 14.66309 | L8: -5.2909337 | M8: 0.28080934 | N8: 1.7730942 | O8: 20.729714 | P8: 6.6739926 | Q8: 12.746681 | R8: 8.4609791 | S8: 7.4196462 | T8: -1.671191 | U8: 5.7293373
C9: III TRIM | D9: 2.1629297 | E9: 1.9015734 | F9: 3.4072298 | G9: 26.323942 | H9: 1.8968598 | I9: -7.7492147 | J9: 5.4989406 | K9: 7.2294247 | L9: 0.28762019 | M9: -0.15631669 | N9: 0.74226133 | O9: 35.165719 | P9: 1.844683 | Q9: 14.317519 | R9: 8.5124721 | S9: 6.6445487 | T9: -2.2788874 | U9: 5.5183828
C10: IV TRIM | D10: 2.377678 | E10: -1.4698581 | F10: 0.16801916 | G10: -15.603961 | H10: 3.5853436 | I10: 4.7602916 | J10: 6.0427438 | K10: 5.0713647 | L10: 3.670477 | M10: 0.6869663 | N10: -0.18475074 | O10: 12.651625 | P10: 4.5884576 | Q10: 6.1978073 | R10: 8.4055932 | S10: 19.594058 | T10: 11.360671 | U10: 4.533836
B11: 2004 | C11: I TRIM | D11: 3.2281989 | E11: 4.6014317 | F11: 14.502244 | G11: -3.2851434 | H11: 9.5031629 | I11: 4.1280021 | J11: 6.3069972 | K11: -7.7853406 | L11: 12.456083 | M11: 3.3920139 | N11: -0.63071075 | O11: -33.004532 | P11: 2.9465285 | Q11: -7.2793186 | R11: -4.4807208 | S11: -24.001206 | T11: 300.91669 | U11: -13.975843
C12: II TRIM | D12: 1.7051081 | E12: 1.9468016 | F12: -3.9375418 | G12: 4.9492063 | H12: 4.9376151 | I12: 10.195852 | J12: 5.4964054 | K12: 3.5910355 | L12: 5.0869073 | M12: 2.1317741 | N12: 2.1611975 | O12: -6.8608989 | P12: -2.6180998 | Q12: -0.52855754 | R12: 4.4653794 | S12: 13.993747 | T12: -98.587225 | U12: 23.778439
C13: III TRIM | D13: 1.5703311 | E13: 0.90861476 | F13: 3.7422815 | G13: 9.8457065 | H13: 3.1812852 | I13: 8.3036332 | J13: 4.5584759 | K13: 1.683825 | L13: 2.0650579 | M13: 1.621661 | N13: 3.4121746 | O13: 39.074921 | P13: 9.9184833 | Q13: -6.1460463 | R13: 1.9475077 | S13: -13.822141 | T13: 2.7462469 | U13: 2.0633715
C14: IV TRIM | D14: 1.8947416 | E14: -3.6200376 | F14: 0.029071011 | G14: -1.4193033 | H14: 0.37873868 | I14: -7.0976562 | J14: 3.5440272 | K14: 3.9988749 | L14: -3.1028332 | M14: 2.0489064 | N14: 0.4897988 | O14: 18.742782 | P14: -5.0588463 | Q14: -0.24724719 | R14: 3.0281795 | S14: 49.825457 | T14: 8.7639464 | U14: 4.7470164
B15: 2005 | C15: I TRIM | D15: -0.93019816 | E15: 2.0909501 | F15: 27.040518 | G15: -23.258847 | H15: 2.0160884 | I15: 3.4968546 | J15: 2.5268793 | K15: 4.1220389 | L15: 0.60158427 | M15: 3.3252446 | N15: -8.4785908 | O15: -34.921235 | P15: 15.2735 | Q15: 9.516983 | R15: -0.31198511 | S15: -19.814857 | T15: 77.327039 | U15: 4.714335
C16: II TRIM | D16: 0.89995652 | E16: 2.9586868 | F16: -4.1360717 | G16: 9.6562176 | H16: 1.9746495 | I16: -0.57132052 | J16: 2.5541369 | K16: 1.3406482 | L16: -5.9417961 | M16: 2.7665546 | N16: -12.055517 | O16: 22.278693 | P16: -3.0244675 | Q16: 0.57071393 | R16: 0.4287413 | S16: 1.5969187 | T16: 6.2778533 | U16: 2.4805821
C17: III TRIM | D17: 2.4534016 | E17: 4.1079065 | F17: 2.6606713 | G17: 1.5414231 | H17: 1.8159555 | I17: 2.4319927 | J17: 2.3965586 | K17: 0.31048241 | L17: -4.9275547 | M17: 1.9527653 | N17: -10.279308 | O17: 28.492418 | P17: -3.9501274 | Q17: -2.3996726 | R17: 2.2846425 | S17: -4.6150902 | T17: -2.0568458 | U17: 0.78733285
C18: IV TRIM | D18: 4.2546773 | E18: 1.0970539 | F18: -1.6380085 | G18: -15.55256 | H18: 1.0577238 | I18: 9.3211861 | J18: 2.2310944 | K18: 0.81560867 | L18: 0.76762545 | M18: 1.4260553 | N18: -2.543952 | O18: 24.360171 | P18: 7.0320696 | Q18: -0.099048816 | R18: 5.1503009 | S18: 36.475256 | T18: 3441.9989 | U18: -11.116274
B19: 2006 | C19: I TRIM | D19: 3.9632101 | E19: 10.364063 | F19: 16.113878 | G19: 36.124403 | H19: 3.0738347 | I19: 6.5374936 | J19: 2.0248721 | K19: 3.4880695 | L19: 21.923694 | M19: 1.9489947 | N19: 11.329865 | O19: -44.009402 | P19: 3.830128 | Q19: 5.0341997 | R19: 7.9777936 | S19: -30.824931 | T19: -76.743194 | U19: 16.306504
C20: II TRIM | D20: 3.1229682 | E20: 4.7942371 | F20: -4.8553539 | G20: -2.8987179 | H20: 2.1296202 | I20: -0.57583784 | J20: 3.0178343 | K20: -1.6976767 | L20: 5.3494723 | M20: 2.0053882 | N20: 9.2789911 | O20: 9.3022293 | P20: 14.596714 | Q20: 0.73107854 | R20: 2.7330213 | S20: 8.3317561 | T20: 5.216556 | U20: 3.010271
C21: III TRIM | D21: 2.2453776 | E21: 3.8734035 | F21: 4.2378375 | G21: 14.980697 | H21: 1.5602118 | I21: 4.4961455 | J21: 3.7022663 | K21: 0.50475571 | L21: 5.8085965 | M21: 0.84544432 | N21: 5.8645938 | O21: 50.37939 | P21: -18.470529 | Q21: -1.3832999 | R21: -0.81220364 | S21: 15.462031 | T21: 7.6386728 | U21: 1.5972162
C22: IV TRIM | D22: 2.0381642 | E22: 5.1756278 | F22: -0.44381296 | G22: -3.1364944 | H22: 0.97599848 | I22: 13.227389 | J22: 4.3728799 | K22: 2.4873895 | L22: 2.6585186 | M22: 0.61598762 | N22: 1.6723877 | O22: 47.172189 | P22: 20.106443 | Q22: 9.6555891 | R22: -3.6930951 | S22: 33.888221 | T22: 77.485079 | U22: 3.5696819
B23: 2007 | C23: I TRIM | D23: 0.22397435 | E23: -0.60399568 | F23: 23.440288 | G23: 3.7626518 | H23: 0.38775764 | I23: -43.873184 | J23: 4.8534852 | K23: 6.0270715 | L23: 0.73878803 | M23: 2.0303576 | N23: -1.8030757 | O23: -47.541291 | P23: 5.5756271 | Q23: -1.8979361 | R23: -4.6038054 | S23: -14.13022 | T23: -29.044603 | U23: 5.0653863
C24: II TRIM | D24: 0.51601594 | E24: -0.41394544 | F24: -4.6798237 | G24: -15.11065 | H24: 0.58262271 | I24: 96.817788 | J24: 4.212302 | K24: 2.1694684 | L24: 3.5978935 | M24: 2.560183 | N24: 0.90051206 | O24: 9.5310018 | P24: 0.86451393 | Q24: 0.2849357 | R24: -5.6681355 | S24: -2.7945601 | T24: -48.132935 | U24: 2.7481968
C25: III TRIM | D25: 1.0617613 | E25: 0.83303817 | F25: 3.3607588 | G25: 33.63152 | H25: 0.81416466 | I25: 1.6735298 | J25: 3.5211135 | K25: 3.5012841 | L25: 1.1376993 | M25: 2.8498582 | N25: 4.1795263 | O25: 27.387218 | P25: -0.63925519 | Q25: -0.27130974 | R25: -2.8264766 | S25: 4.0562548 | T25: -89.486778 | U25: 2.9277902
C26: IV TRIM | D26: 2.0609912 | E26: 0.38123715 | F26: -0.046577382 | G26: 27.090958 | H26: 1.632766 | I26: -1.7322031 | J26: 2.8067403 | K26: 4.2700128 | L26: -0.22096819 | M26: 4.9122976 | N26: 7.9468097 | O26: 16.866116 | P26: -7.0766632 | Q26: 0.99733588 | R26: 1.8618201 | S26: -3.2421279 | T26: 4227.3972 | U26: -1.3264953
B27: 2008 | C27: I TRIM | D27: 1.8542164 | E27: -0.27524738 | F27: 12.260652 | G27: -20.835478 | H27: 1.0398726 | I27: 0.73775131 | J27: 2.0009201 | K27: 6.0971405 | L27: 4.1365764 | M27: 6.3939626 | N27: 12.147913 | O27: -43.260063 | P27: -5.1690882 | Q27: 6.1647021 | R27: 4.7338395 | S27: -7.1693358 | T27: -67.516838 | U27: 5.0414728
C28: II TRIM | D28: 1.174066 | E28: 0.91558675 | F28: -4.3674617 | G28: 5.4349134 | H28: 0.26915959 | I28: -18.956536 | J28: 1.6176683 | K28: 3.2673449 | L28: 3.2549855 | M28: 4.9330917 | N28: 10.212578 | O28: 8.4453452 | P28: 9.8967326 | Q28: 1.763927 | R28: 1.4865877 | S28: 31.323576 | T28: 108.04253 | U28: -0.49086049
C29: III TRIM | D29: 1.0985593 | E29: 2.0547297 | F29: 2.5749656 | G29: 0.9129477 | H29: 0.44835267 | I29: 25.603548 | J29: 1.2327464 | K29: 3.0814423 | L29: 1.7635475 | M29: 3.5413159 | N29: 7.9181997 | O29: 42.599346 | P29: 12.87448 | Q29: 2.1234167 | R29: 1.4951517 | S29: 7.0218903 | T29: -19.739425 | U29: 3.3618776
C30: IV TRIM | D30: 1.5234928 | E30: 0.61001613 | F30: -0.86676176 | G30: -35.543909 | H30: 2.5056716 | I30: -0.46195961 | J30: 0.95290054 | K30: 2.100542 | L30: 1.6831806 | M30: 1.0579261 | N30: 5.7578114 | O30: 60.282806 | P30: 6.1240501 | Q30: 3.2971811 | R30: 1.261061 | S30: -2.5003671 | T30: -81.743684 | U30: 11.501129
B31: 2009 | C31: I TRIM | D31: 0.78557366 | E31: 3.3383217 | F31: -4.690549 | G31: 12.653582 | H31: 3.9061982 | I31: -13.082792 | J31: 0.57477942 | K31: 1.2398643 | L31: 3.3829296 | M31: -1.1927402 | N31: 4.8381067 | O31: -41.428443 | P31: 0.27812433 | Q31: -6.1911938 | R31: 0.87414857 | S31: 2.8751486 | T31: 23.895153 | U31: -11.409708
C32: II TRIM | D32: 0.99635506 | E32: 2.0588389 | F32: -3.4259231 | G32: 50.190559 | H32: 2.10085 | I32: 20.392159 | J32: 1.7458042 | K32: 1.5078088 | L32: 5.6021229 | M32: 0.56263388 | N32: 4.5116814 | O32: -3.6720694 | P32: 4.4278774 | Q32: 10.757129 | R32: 0.39668368 | S32: -20.031407 | T32: 92.266189 | U32: 4.0847275
C33: III TRIM | D33: 2.0912562 | E33: 1.4689642 | F33: 3.2581273 | G33: -8.6566986 | H33: 2.2592904 | I33: -0.56527023 | J33: 2.5500902 | K33: 1.8553348 | L33: 3.0408666 | M33: 0.94783812 | N33: 2.4645947 | O33: 40.753042 | P33: -6.3354365 | Q33: 3.4422564 | R33: 1.4974472 | S33: 17.014002 | T33: -4.8551999 | U33: 1.562592
C34: IV TRIM | D34: 3.544543 | E34: -1.726564 | F34: -0.40330604 | G34: -7.9768192 | H34: 1.6037419 | I34: 1.9996301 | J34: 3.4648873 | K34: 1.7019043 | L34: 2.6452594 | M34: 2.9016771 | N34: -1.0581189 | O34: -18.227923 | P34: 14.765302 | Q34: 1.5063905 | R34: 2.873329 | S34: -6.5411706 | T34: 371.89851 | U34: 3.1509737
B35: 2010 | C35: I TRIM | D35: 3.6731749 | E35: -0.95790185 | F35: 2.0679392 | G35: -0.34132762 | H35: 2.0522911 | I35: 1.5944588 | J35: 4.0285608 | K35: 1.513515 | L35: -1.5035808 | M35: 2.2519444 | N35: -4.6496242 | O35: -23.173955 | P35: -4.3922725 | Q35: -1.217227 | R35: 2.4748013 | S35: -17.24542 | T35: -97.657968 | U35: -0.86643132
C36: II TRIM | D36: 2.5756728 | E36: 1.4015806 | F36: -2.9944528 | G36: -9.0504705 | H36: 2.8837664 | I36: -5.3621751 | J36: 3.1142202 | K36: 2.4566061 | L36: 7.0352693 | M36: 2.3587963 | N36: 0.39985429 | O36: 15.38269 | P36: 8.5534235 | Q36: 1.734517 | R36: 3.3451261 | S36: 19.87341 | T36: 237.11221 | U36: 6.0034021
C37: III TRIM | D37: 2.1862019 | E37: 2.9996778 | F37: -0.95070911 | G37: 6.0899644 | H37: 2.5947123 | I37: 9.0647534 | J37: 2.1202289 | K37: 3.088106 | L37: 3.3635275 | M37: 2.7307594 | N37: 8.5684738 | O37: 18.322298 | P37: -6.9923856 | Q37: 1.0711029 | R37: 3.4745847 | S37: 28.134143 | T37: -40.732528 | U37: -0.29021808
C38: IV TRIM | D38: 2.305943 | E38: -1.1929973 | F38: -8.2722817 | G38: -5.0574975 | H38: 1.7879134 | I38: 8.1556726 | J38: 1.2003136 | K38: 2.9041492 | L38: 3.0995027 | M38: 4.5590876 | N38: 18.751771 | O38: 31.921771 | P38: -9.1949748 | Q38: 0.34039195 | R38: 3.3866839 | S38: 2.8065767 | T38: 3603.9274 | U38: -9.128041
B39: 2011 | C39: I TRIM | D39: 1.2098562 | E39: 7.1272825 | F39: 2.6984167 | G39: 0.028576046 | H39: 2.7204394 | I39: -3.4118559 | J39: 0.19613634 | K39: 1.5395366 | L39: -5.0404507 | M39: -0.2500128 | N39: 26.26733 | O39: -34.591254 | P39: 8.9745656 | Q39: 0.36657184 | R39: 0.76220581 | S39: -25.500736 | T39: -98.31662 | U39: 6.4870072
C40: II TRIM | D40: 0.85402834 | E40: 4.3663262 | F40: -9.4992592 | G40: 20.900774 | H40: 2.4440482 | I40: 0.44548806 | J40: 2.4451271 | K40: 2.1391453 | L40: 7.3912067 | M40: 1.1882391 | N40: 18.652926 | O40: -14.438412 | P40: -2.6733482 | Q40: 0.74556091 | R40: 2.4701143 | S40: 13.199452 | T40: -4.1431914 | U40: 0.88769692
...

Sheet Q4
C1: Quadro 4 - Contribuição % das Actividades Económicas na Taxa de Crescimento do PIB Trimestral Ajustado Sazonalmente
B2: Período | D2: Agro-Pecuária e Silvicultura | E2: Pesca e Aquicultura | F2: Extracção e Refino de Petróleo | G2: Extracção de Diamantes, Minerais Metálicos e de Outros Minerais não Metálicos | H2: Produtos da Indústria Transformadora | I2: Produção de Electricidade, Água e Saneamento | J2: Construção | K2: Comércio e Raparação de Veiculos | L2: Serviço de Alojamento e Restauração | M2: Transportes e Armazenagem | N2: Actividades de informação e de comunicação | O2: Intermediação Financeira e de Seguros | P2: Administração Pública, Defesa e Segurança Social Obrigatória | Q2: Serviços Imobiliários e Aluguer | R2: Outros Serviços | S2: Imposto sobre os produtos | T2: Subsídios (-) | U2: PRODUCTO INTERNO BRUTO
B3: 2002 | C3: I TRIM | D3: 0 | E3: 0 | F3: 0 | G3: 0 | H3: 0 | I3: 0 | J3: 0 | K3: 0 | L3: 0 | M3: 0 | N3: 0 | O3: 0 | P3: 0 | Q3: 0 | R3: 0 | S3: 0 | T3: 0 | U3: 0
C4: II TRIM | D4: 0.056364474 | E4: 0.041063066 | F4: -1.3712752 | G4: -0.098049594 | H4: -0.077366037 | I4: 0.065558132 | J4: 0.1477209 | K4: 1.5330143 | L4: -0.34265066 | M4: -0.0092050456 | N4: 0.015808123 | O4: 0.22486688 | P4: 0.97048627 | Q4: 0.31433555 | R4: 0.41575691 | S4: 0.38541429 | T4: -0.18584062 | U4: 2.0860017
C5: III TRIM | D5: 0.15791107 | E5: 0.01810387 | F5: 0.65089449 | G5: 0.18372147 | H5: 0.016280245 | I5: 0.073639863 | J5: 0.19845601 | K5: 1.4197658 | L5: -0.11069729 | M5: -0.033722043 | N5: 0.0076483953 | O5: 0.6364918 | P5: 0.40334058 | Q5: 0.18915125 | R5: 0.58466534 | S5: 0.35675312 | T5: -0.1696334 | U5: 4.5827706
C6: IV TRIM | D6: 0.18723533 | E6: -0.069548211 | F6: -0.10613977 | G6: -0.040904832 | H6: 0.093751356 | I6: -0.044074861 | J6: 0.28603749 | K6: 1.9244796 | L6: -0.069518402 | M6: -0.042386199 | N6: 0.010053868 | O6: 0.4575568 | P6: 1.2132515 | Q6: 0.74540283 | R6: 0.94683695 | S6: 1.0629578 | T6: -0.38627301 | U6: 6.1687182
B7: 2003 | C7: I TRIM | D7: 0.61527262 | E7: 0.12016899 | F7: -0.48446279 | G7: -0.10498997 | H7: 0.20148932 | I7: 0.13502266 | J7: 0.46267182 | K7: -4.7088449 | L7: 0.68694482 | M7: 0.10295689 | N7: 0.038556431 | O7: -1.7520321 | P7: -1.5721665 | Q7: -1.8518804 | R7: -2.2428854 | S7: -1.4291933 | T7: 0.66732986 | U7: -11.116042
C8: II TRIM | D8: 0.41534593 | E8: 0.059616561 | F8: -1.3561314 | G8: 0.22567292 | H8: 0.046147216 | I8: 0.004346985 | J8: 0.63925917 | K8: 2.3378162 | L8: -0.18096268 | M8: 0.018358485 | N8: 0.03480608 | O8: 0.50760839 | P8: 1.1918193 | Q8: 0.73741549 | R8: 0.65587826 | S8: 0.36402149 | T8: 0.028318907 | U8: 5.7293373
C9: III TRIM | D9: 0.31623098 | E9: 0.026965671 | F9: 0.66706051 | G9: 0.27022582 | H9: 0.11502146 | I9: -0.073122261 | J9: 0.57431388 | K9: 1.0046779 | L9: 0.0070824297 | M9: -0.0077904597 | N9: 0.011272695 | O9: 0.79028508 | P9: 0.26712814 | Q9: 0.70990677 | R9: 0.5440596 | S9: 0.26619976 | T9: 0.028864809 | U9: 5.5183828
C10: IV TRIM | D10: 0.34524325 | E10: -0.020647678 | F10: 0.03306666 | G10: -0.19670403 | H10: 0.21535354 | I10: 0.040282124 | J10: 0.64724598 | K10: 0.73464708 | L10: 0.088114936 | M10: 0.033230017 | N10: -0.0027478032 | O10: 0.3735889 | P10: 0.65783923 | Q10: 0.34150826 | R10: 0.56670312 | S10: 0.81380815 | T10: -0.13669575 | U10: 4.533836
B11: 2004 | C11: I TRIM | D11: 2.5393284 | E11: 0.3370071 | F11: 15.127841 | G11: -0.18494216 | H11: 3.1287357 | I11: 0.19364066 | J11: 3.7907044 | K11: -6.270426 | L11: 1.6403812 | M11: 0.87419268 | N11: -0.049545897 | O11: -5.8095144 | P11: 2.3379144 | Q11: -2.2539826 | R11: -1.7328779 | S11: -6.3084324 | T11: -21.335867 | U11: -13.975843
C12: II TRIM | D12: 0.90403215 | E12: 0.097382387 | F12: -3.0708312 | G12: 0.17594842 | H12: 1.1623037 | I12: 0.32517917 | J12: 2.2930468 | K12: 1.7414625 | L12: 0.49189801 | M12: 0.37089651 | N12: 0.11015371 | O12: -0.52828432 | P12: -1.396339 | Q12: -0.099084049 | R12: 1.0770714 | S12: 1.8251734 | T12: 18.29843 | U12: 23.778439
C13: III TRIM | D13: 0.12564604 | E13: 0.0068753526 | F13: 0.41600999 | G13: 0.054507807 | H13: 0.1166055 | I13: 0.043302748 | J13: 0.29769692 | K13: 0.12551522 | L13: 0.031137587 | M13: 0.042757802 | N13: 0.026363602 | O13: 0.41581457 | P13: 0.76438304 | Q13: -0.17005467 | R13: 0.072814948 | S13: -0.30493643 | T13: -0.0010685346 | U13: 2.0633715
C14: IV TRIM | D14: 0.47064848 | E14: -0.084484833 | F14: 0.010247206 | G14: -0.026381067 | H14: 0.043780354 | I14: -0.12252579 | J14: 0.73966181 | K14: 0.92642737 | L14: -0.14595214 | M14: 0.16779767 | N14: 0.011961486 | O14: 0.84782596 | P14: -1.3098158 | Q14: -0.019624515 | R14: 0.35279452 | S14: 2.8953643 | T14: -0.010708704 | U14: 4.7470164
B15: 2005 | C15: I TRIM | D15: -0.095575758 | E15: 0.019092813 | F15: 3.8704406 | G15: -0.17300993 | H15: 0.094965251 | I15: 0.022766205 | J15: 0.22167643 | K15: 0.40316991 | L15: 0.01113098 | M15: 0.11281571 | N15: -0.084466964 | O15: -0.76145332 | P15: 1.5241427 | Q15: 0.3058902 | R15: -0.015202112 | S15: -0.70032933 | T15: -0.041718374 | U15: 4.714335
C16: II TRIM | D16: 0.34833558 | E16: 0.27644461 | F16: -0.84447256 | G16: 0.30736704 | H16: 0.35201866 | I16: -0.0043224488 | J16: 0.50342076 | K16: 0.39877638 | L16: -0.12418505 | M16: 0.35436935 | N16: -0.12341888 | O16: 0.60044668 | P16: -0.39063872 | Q16: 0.26803269 | R16: 0.26885993 | S16: 0.29629166 | T16: -0.0067436021 | U16: 2.4805821
C17: III TRIM | D17: 0.20361651 | E17: 0.031859343 | F17: 0.37477783 | G17: 0.007796615 | H17: 0.071905322 | I17: 0.013166002 | J17: 0.17862975 | K17: 0.025892808 | L17: -0.069712342 | M17: 0.056845235 | N17: -0.066603672 | O17: 0.39949641 | P17: -0.35606526 | Q17: -0.068645339 | R17: 0.090059405 | S17: -0.10737565 | T17: 0.0016898776 | U17: 0.78733285
C18: IV TRIM | D18: 14.207174 | E18: 0.34785504 | F18: -9.301934 | G18: -3.136893 | H18: 1.6746125 | I18: 2.0298728 | J18: 6.6871243 | K18: 2.6794191 | L18: 0.40546428 | M18: 1.6620717 | N18: -0.58077268 | O18: 17.235019 | P18: 23.909407 | Q18: -0.10860004 | R18: 8.1550044 | S18: 31.788788 | T18: -108.76989 | U18: -11.116274
B19: 2006 | C19: I TRIM | D19: 1.1405586 | E19: 0.27464569 | F19: 7.4407788 | G19: 0.5086498 | H19: 0.40656121 | I19: 0.12866106 | J19: 0.51290384 | K19: 0.95500493 | L19: 0.9646547 | M19: 0.19046162 | N19: 0.20838415 | O19: -3.2010474 | P19: 1.1522501 | Q19: 0.45584231 | R19: 1.0980416 | S19: -3.0308576 | T19: 7.1010101 | U19: 16.306504
C20: II TRIM | D20: 0.50788512 | E20: 0.076214505 | F20: -1.4150477 | G20: -0.030200064 | H20: 0.15781335 | I20: -0.0065627562 | J20: 0.42392354 | K20: -0.26146496 | L20: 0.15599294 | M20: 0.10859902 | N20: 0.10327617 | O20: 0.20591904 | P20: 2.4783332 | Q20: 0.037794333 | R20: 0.22078076 | S20: 0.30803305 | T20: -0.061018558 | U20: 3.010271
C21: III TRIM | D21: 0.7023024 | E21: 0.12034546 | F21: 2.1915949 | G21: 0.28264437 | H21: 0.22022078 | I21: 0.095016672 | J21: 0.99920282 | K21: 0.142523 | L21: 0.3327967 | M21: 0.087099778 | N21: 0.13303178 | O21: 2.2733842 | P21: -6.7025109 | Q21: -0.13434575 | R21: -0.12571139 | S21: 1.1549536 | T21: -0.17533213 | U21: 1.5972162
C22: IV TRIM | D22: 0.1704024 | E22: 0.043667915 | F22: -0.062545985 | G22: -0.017788358 | H22: 0.036576788 | I22: 0.076364572 | J22: 0.31996309 | K22: 0.18454072 | L22: 0.042133403 | M22: 0.016730865 | N22: 0.010499371 | O22: 0.83685911 | P22: 1.555128 | Q22: 0.24176582 | R22: -0.14822331 | S22: 0.76408914 | T22: -0.50048156 | U22: 3.5696819
B23: 2007 | C23: I TRIM | D23: 0.033501308 | E23: -0.0093975074 | F23: 5.76627 | G23: 0.036241809 | H23: 0.025727599 | I23: -0.50284341 | J23: 0.64988725 | K23: 0.80350672 | L23: 0.021074923 | M23: 0.097285977 | N23: -0.02017937 | O23: -2.1763431 | P23: 0.90814508 | Q23: -0.09136772 | R23: -0.31200727 | S23: -0.74791265 | T23: 0.58379667 | U23: 5.0653863
C24: II TRIM | D24: 0.24130764 | E24: -0.019969341 | F24: -4.4329343 | G24: -0.47109979 | H24: 0.12105422 | I24: 1.9428176 | J24: 1.8448435 | K24: 0.95659063 | L24: 0.32252548 | M24: 0.39043701 | N24: 0.030871228 | O24: 0.71397892 | P24: 0.46373517 | Q24: 0.041976777 | R24: -1.1431202 | S24: -0.3962129 | T24: 2.1413951 | U24: 2.7481968
C25: III TRIM | D25: 0.11663751 | E25: 0.0093530266 | F25: 0.70917284 | G25: 0.2080164 | H25: 0.039764528 | I25: 0.015446951 | J25: 0.37558407 | K25: 0.3686289 | L25: 0.024692339 | M25: 0.10417179 | N25: 0.033787255 | O25: 0.52517003 | P25: -0.080831161 | Q25: -0.0093676662 | R25: -0.12566768 | S25: 0.13064689 | T25: 0.48258422 | U25: 2.9277902
C26: IV TRIM | D26: 0.22739894 | E26: 0.0042894284 | F26: -0.010096239 | G26: 0.22253506 | H26: 0.079899337 | I26: -0.016155862 | J26: 0.30801538 | K26: 0.46243537 | L26: -0.0048204956 | M26: 0.18353941 | N26: 0.066514318 | O26: 0.40945581 | P26: -0.88361282 | Q26: 0.034130424 | R26: 0.079942542 | S26: -0.10799068 | T26: -2.3819752 | U26: -1.3264953
B27: 2008 | C27: I TRIM | D27: 0.25825992 | E27: -0.003845072 | F27: 3.2856424 | G27: -0.26903992 | H27: 0.063967243 | I27: 0.0083632883 | J27: 0.27921968 | K27: 0.85159289 | L27: 0.11136963 | M27: 0.31000285 | N27: 0.13575578 | O27: -1.5180716 | P27: -0.74181695 | Q27: 0.26354014 | R27: 0.2560883 | S27: -0.28578925 | T27: 2.0362335 | U27: 5.0414728
C28: II TRIM | D28: 0.12844173 | E28: 0.0098360732 | F28: -1.0132145 | G28: 0.042842468 | H28: 0.012900845 | I28: -0.16693842 | J28: 0.17756111 | K28: 0.37337263 | L28: 0.070374624 | M28: 0.19623197 | N28: 0.098700929 | O28: 0.12967294 | P28: 0.038634067 | Q28: 0.06173528 | R28: 0.064951886 | S28: 0.10025456 | T28: -0.81621867 | U28: -0.49086049
C29: III TRIM | D29: 0.088688047 | E29: 0.016247779 | F29: 0.41668532 | G29: 0.0055344056 | H29: 0.015716441 | I29: 0.13328285 | J29: 0.10029058 | K29: 0.26523042 | L29: 0.028716004 | M29: 0.10781682 | N29: 0.061518007 | O29: 0.51737397 | P29: 1.0830388 | Q29: 0.055162088 | R29: 0.048356394 | S29: 0.19193401 | T29: 0.22628574 | U29: 3.3618776
C30: IV TRIM | D30: 0.53745327 | E30: 0.021277837 | F30: -0.62185854 | G30: -0.93983342 | H30: 0.38134245 | I30: -0.013055507 | J30: 0.33921004 | K30: 0.80555441 | L30: 0.12055175 | M30: 0.14414666 | N30: 0.20866118 | O30: 4.512595 | P30: 2.5134053 | Q30: 0.37808315 | R30: 0.17892201 | S30: -0.31614624 | T30: 3.2508197 | U30: 11.501129
B31: 2009 | C31: I TRIM | D31: 0.47227031 | E31: 0.19664931 | F31: -5.5997897 | G31: 0.36199289 | H31: 1.0228926 | I31: -0.61775481 | J31: 0.34671931 | K31: 0.81489675 | L31: 0.41354405 | M31: -0.27567815 | N31: 0.31124975 | O31: -8.3436357 | P31: 0.20333563 | Q31: -1.230961 | R31: 0.21081053 | S31: 0.5949554 | T31: -0.2912048 | U31: -11.409708
C32: II TRIM | D32: 1.0635086 | E32: 0.22078664 | F32: -6.8673058 | G32: 2.8495636 | H32: 1.0070176 | I32: 1.4743801 | J32: 1.8658907 | K32: 1.7674659 | L32: 1.2472544 | M32: 0.22635808 | N32: 0.5360631 | O32: -0.76309593 | P32: 5.7187491 | Q32: 3.5345542 | R32: 0.17000278 | S32: -7.5122632 | T32: -2.4542024 | U32: 4.0847275
C33: III TRIM | D33: 0.15806425 | E33: 0.011272133 | F33: 0.44221271 | G33: -0.051754139 | H33: 0.077524192 | I33: -0.0034498038 | J33: 0.19442699 | K33: 0.15478196 | L33: 0.050126372 | M33: 0.026886531 | N33: 0.021457626 | O33: 0.57197146 | P33: -0.59909029 | Q33: 0.087830833 | R33: 0.045172739 | S33: 0.35774957 | T33: 0.017408913 | U33: 1.562592
C34: IV TRIM | D34: 2.1110864 | E34: -0.10376278 | F34: -0.4362676 | G34: -0.33622504 | H34: 0.43434343 | I34: 0.093660583 | J34: 2.0910143 | K34: 1.1162148 | L34: 0.34679872 | M34: 0.64132405 | N34: -0.072857669 | O34: -2.77933 | P34: 10.094021 | Q34: 0.3068811 | R34: 0.67904129 | S34: -1.242215 | T34: -9.7927542 | U34: 3.1509737
B35: 2010 | C35: I TRIM | D35: 0.40529654 | E35: -0.36471093 | F35: 0.39862013 | G35: -0.0023687939 | H35: 0.10104289 | I35: 0.013629421 | J35: 0.45005863 | K35: 0.1806287 | L35: -0.036202053 | M35: 0.091636156 | N35: -0.30667573 | O35: -0.5169713 | P35: -0.61656669 | Q35: -0.29503559 | R35: 0.10764956 | S35: -0.54763817 | T35: 0.071175915 | U35: -0.86643132
C36: II TRIM | D36: 0.65319802 | E36: 0.032519791 | F36: -1.3061251 | G36: -0.13877096 | H36: 0.32122261 | I36: -0.1032361 | J36: 0.8023753 | K36: 0.65980545 | L36: 0.36988274 | M36: 0.21758436 | N36: 0.01030291 | O36: 0.58447173 | P36: 2.5449557 | Q36: 0.14054019 | R36: 0.33056584 | S36: 1.1578195 | T36: -0.2737099 | U36: 6.0034021
C37: III TRIM | D37: 0.2441135 | E37: 0.030293677 | F37: -0.92145832 | G37: 0.036454036 | H37: 0.12763949 | I37: 0.070894791 | J37: 0.24178676 | K37: 0.36476698 | L37: 0.081247164 | M37: 0.11067482 | N37: 0.095147569 | O37: 0.34479012 | P37: -1.7182096 | Q37: 0.037898712 | R37: 0.15231454 | S37: 0.34338909 | T37: 0.068038608 | U37: -0.29021808
C38: IV TRIM | D38: 0.61705759 | E38: -0.029102887 | F38: -3.4900116 | G38: -0.075322408 | H38: 0.21161706 | I38: 0.16314955 | J38: 0.32782316 | K38: 0.82934295 | L38: 0.18149134 | M38: 0.44517132 | N38: 0.53018031 | O38: 1.6669086 | P38: -2.7806041 | Q38: 0.028548475 | R38: 0.36027172 | S38: 0.25282465 | T38: -8.3673867 | U38: -9.128041
B39: 2011 | C39: I TRIM | D39: 0.23482838 | E39: 0.12179996 | F39: 0.74037203 | G39: 0.00028647728 | H39: 0.23236906 | I39: -0.05233653 | J39: 0.038434717 | K39: 0.32075761 | L39: -0.21573901 | M39: -0.018097231 | N39: 0.62528237 | O39: -1.6894542 | P39: 1.7472328 | Q39: 0.021871439 | R39: 0.059433487 | S39: -1.6743836 | T39: 5.9943494 | U39: 6.4870072
C40: II TRIM | D40: 0.10457442 | E40: 0.049825648 | F40: -0.6195312 | G40: 0.13064357 | H40: 0.13366552 | I40: 0.0041142215 | J40: 0.2992482 | K40: 0.28208237 | L40: 0.18725216 | M40: 0.053478607 | N40: 0.34947147 | O40: -0.28750732 | P40: -0.35353429 | Q40: 0.027829411 | R40: 0.12097265 | S40: 0.40246086 | T40: 0.0026506092 | U40: 0.88769692
...

Sheet Q5
C1: Quadro 5 - PIB_Trimestral_Medidas de Volume Encadeadas (Não Ajustada) em Milhões de Kwanzas
B2: Período | D2: Agro-Pecuária e Silvicultura | E2: Pesca e Aquicultura | F2: Extracção e Refino de Petróleo | G2: Extracção de Diamantes, Minerais Metálicos e de Outros Minerais não Metálicos | H2: Produtos da Indústria Transformadora | I2: Produção de Electricidade, Água e Saneamento | J2: Construção | K2: Comércio e Raparação de Veiculos | L2: Serviço de Alojamento e Restauração | M2: Transportes e Armazenagem | N2: Actividades de informação e de comunicação | O2: Intermediação Financeira e de Seguros | P2: Administração Pública, Defesa e Segurança Social Obrigatória | Q2: Serviços Imobiliários e Aluguer | R2: Outros Serviços | S2: Imposto sobre os produtos | T2: Subsídios (-) | U2: PRODUCTO INTERNO BRUTO
C3: Total | D3: 800987.73 | E3: 77872.749 | F3: 1241999.6 | G3: 52753.794 | H3: 343694.49 | I3: 48482.873 | J3: 546962.88 | K3: 790988.99 | L3: 133026.19 | M3: 292468.33 | N3: 85675.553 | O3: 147431.97 | P3: 806221.95 | Q3: 301299.7 | R3: 385439.86 | S3: 222286.59 | T3: -81835.93 | U3: 6423975.2
B4: 2002 | C4: I TRIM | D4: 237453.81 | E4: 19740.821 | F4: 317550.06 | G4: 12771.318 | H4: 78888.935 | I4: 11424.11 | J4: 140722.35 | K4: 148430.62 | L4: 14850.66 | M4: 65360.207 | N4: 20542.965 | O4: 28349.376 | P4: 159794.14 | Q4: 63478.074 | R4: 72333.17 | S4: 45536.408 | T4: -16118.798 | U4: 1540753.9
C5: II TRIM | D5: 299687.38 | E5: 16627.256 | F5: 302058.3 | G5: 11663.619 | H5: 80538.539 | I5: 12569.502 | J5: 127334.28 | K5: 174626.93 | L5: 31893.062 | M5: 68525.215 | N5: 20950.509 | O5: 30889.772 | P5: 161831.71 | Q5: 66886.011 | R5: 92357.694 | S5: 49890.561 | T5: -18218.301 | U5: 1524907.5
C6: III TRIM | D6: 161270.24 | E6: 15513.201 | F6: 312003.28 | G6: 14470.689 | H6: 83878.18 | I6: 12766.921 | J6: 142891.31 | K6: 213059.81 | L6: 40385.979 | M6: 79381.91 | N6: 20652.637 | O6: 40614.693 | P6: 184516.94 | Q6: 79170.697 | R6: 108935.8 | S6: 55341.372 | T6: -20810.12 | U6: 1579032.4
C7: IV TRIM | D7: 102576.3 | E7: 25991.469 | F7: 310387.97 | G7: 13848.169 | H7: 100388.84 | I7: 11722.34 | J7: 136014.94 | K7: 254871.63 | L7: 45896.492 | M7: 79201.002 | N7: 23529.442 | O7: 47578.133 | P7: 300079.16 | Q7: 91764.921 | R7: 111813.2 | S7: 71518.252 | T7: -26688.71 | U7: 1779281.4
C8: Total | D8: 868257.84 | E8: 83774.355 | F8: 1193872.7 | G8: 63202.361 | H8: 365103.72 | I8: 54318.205 | J8: 636766.3 | K8: 840860.07 | L8: 149765.68 | M8: 295128.84 | N8: 89765.532 | O8: 156326.8 | P8: 867393.6 | Q8: 310511.59 | R8: 395070.88 | S8: 253210.75 | T8: -76488.245 | U8: 6647999.3
B9: 2003 | C9: I TRIM | D9: 252936.79 | E9: 20851.582 | F9: 304845.65 | G9: 12647.069 | H9: 81801.342 | I9: 14183.697 | J9: 155887.15 | K9: 161932.52 | L9: 15780.125 | M9: 65217.624 | N9: 21409.269 | O9: 27534.652 | P9: 175368.13 | Q9: 60308.589 | R9: 74684.034 | S9: 55168.09 | T9: -19054.368 | U9: 1553375
C10: II TRIM | D10: 325152.23 | E10: 17835.732 | F10: 289596.49 | G10: 15184.672 | H10: 85093.411 | I10: 14578.159 | J10: 146117.18 | K10: 197920.3 | L10: 34880.486 | M10: 68624.714 | N10: 22044.721 | O10: 33242.507 | P10: 178972.66 | Q10: 68900.168 | R10: 97862.77 | S10: 59261.368 | T10: -18735.933 | U10: 1592816.4
C11: III TRIM | D11: 176676.76 | E11: 16801.624 | F11: 299463.71 | G11: 19181.876 | H11: 89879.45 | I11: 12558.002 | J11: 169203.12 | K11: 229401.71 | L11: 45556.034 | M11: 80170.617 | N11: 21754.902 | O11: 44932.474 | P11: 200765.46 | Q11: 87500.933 | R11: 112777.54 | S11: 63199.018 | T11: -18308.962 | U11: 1661391.3
C12: IV TRIM | D12: 113492.06 | E12: 28285.416 | F12: 299966.87 | G12: 16188.743 | H12: 108329.52 | I12: 12998.347 | J12: 165558.84 | K12: 251605.54 | L12: 53549.034 | M12: 81115.885 | N12: 24556.64 | O12: 50617.162 | P12: 312287.36 | Q12: 93801.898 | R12: 109746.54 | S12: 75582.27 | T12: -20388.983 | U12: 1840416.5
C13: Total | D13: 952428.53 | E13: 89123.938 | F13: 1358096.9 | G13: 67931.837 | H13: 437606.83 | I13: 61980.151 | J13: 789207.53 | K13: 893128.54 | L13: 178355.3 | M13: 315937.05 | N13: 92978.779 | O13: 161581.29 | P13: 954251.63 | Q13: 317519.66 | R13: 446152.61 | S13: 263895.8 | T13: -85374.781 | U13: 7407191.7
B14: 2004 | C14: I TRIM | D14: 279094.98 | E14: 22631.403 | F14: 343468.79 | G14: 15656.92 | H14: 96006.979 | I14: 14237.876 | J14: 194396.91 | K14: 194487.05 | L14: 19107.014 | M14: 68113.036 | N14: 21777.987 | O14: 33911.205 | P14: 205290.95 | Q14: 78472.667 | R14: 94092.536 | S14: 57441.614 | T14: -81742.836 | U14: 1561623.3
C15: II TRIM | D15: 356903.04 | E15: 19202.378 | F15: 329944.57 | G15: 16431.813 | H15: 104260.85 | I15: 16074.289 | J15: 183321.76 | K15: 214709.96 | L15: 43056.096 | M15: 72915.643 | N15: 22514.553 | O15: 31584.591 | P15: 191839.46 | Q15: 78914.704 | R15: 115030.99 | S15: 65479.848 | T15: -1154.8423 | U15: 1872845
C16: III TRIM | D16: 192980.43 | E16: 17831.825 | F16: 342292.02 | G16: 18049.641 | H16: 110736.18 | I16: 16369.257 | J16: 210433.98 | K16: 232400.22 | L16: 55251.375 | M16: 86438.758 | N16: 22793.444 | O16: 43926.245 | P16: 232150.9 | Q16: 79551.496 | R16: 122707.65 | S16: 56429.131 | T16: -1186.5571 | U16: 1887734.5
C17: IV TRIM | D17: 123450.09 | E17: 29458.332 | F17: 342391.53 | G17: 17793.462 | H17: 126602.82 | I17: 15298.728 | J17: 201054.89 | K17: 251531.31 | L17: 60940.811 | M17: 88469.61 | N17: 25892.795 | O17: 52159.246 | P17: 324970.31 | Q17: 80580.795 | R17: 114321.43 | S17: 84545.204 | T17: -1290.5463 | U17: 2084988.9
C18: Total | D18: 993536.48 | E18: 93522.239 | F18: 1701108.3 | G18: 56672.232 | H18: 472383.81 | I18: 66642.359 | J18: 892236.87 | K18: 985444.8 | L18: 167958.74 | M18: 347568.75 | N18: 74757.387 | O18: 195110.4 | P18: 1074420.8 | Q18: 333259.88 | R18: 476853.61 | S18: 292024.25 | T18: -91477.783 | U18: 8455663.2
B19: 2005 | C19: I TRIM | D19: 290989.9 | E19: 22965.843 | F19: 434975.97 | G19: 13654.908 | H19: 107033.33 | I19: 16228.675 | J19: 227584.98 | K19: 224847.39 | L19: 19371.719 | M19: 74898.892 | N19: 21166.127 | O19: 33944.593 | P19: 240217.74 | Q19: 81307.997 | R19: 104827.21 | S19: 67792.692 | T19: -2288.4876 | U19: 2172002.3
C20: II TRIM | D20: 369019.19 | E20: 19510.867 | F20: 416985.05 | G20: 14973.456 | H20: 112649.09 | I20: 16501.889 | J20: 208658.21 | K20: 241406.89 | L20: 40039.988 | M20: 80458.183 | N20: 18840.223 | O20: 41507.005 | P20: 224915.32 | Q20: 82457.021 | R20: 121459.33 | S20: 68875.287 | T20: -2432.1554 | U20: 2150895.4
C21: III TRIM | D21: 201503.65 | E21: 18649.482 | F21: 428079.65 | G21: 15204.26 | H21: 117695.45 | I21: 16019.355 | J21: 234635.61 | K21: 253915.34 | L21: 50158.344 | M21: 95276.147 | N21: 16534.429 | O21: 53333.354 | P21: 238475.92 | Q21: 84041.556 | R21: 128307.94 | S21: 65696.63 | T21: -2382.1298 | U21: 2140017.6
C22: IV TRIM | D22: 132023.74 | E22: 32396.046 | F22: 421067.67 | G22: 12839.608 | H22: 135005.94 | I22: 17892.44 | J22: 221358.07 | K22: 265275.18 | L22: 58388.692 | M22: 96935.532 | N22: 18216.608 | O22: 66325.45 | P22: 370811.8 | Q22: 85453.305 | R22: 122259.13 | S22: 89659.644 | T22: -84375.011 | U22: 1992747.8
C23: Total | D23: 1126570 | E23: 114368.19 | F23: 1921731 | G23: 72864.228 | H23: 510743.08 | I23: 80540.682 | J23: 992086.79 | K23: 1027321.1 | L23: 212988.14 | M23: 371767.13 | N23: 82767.776 | O23: 228599.76 | P23: 1204399.8 | Q23: 354415.52 | R23: 545240.03 | S23: 310658.84 | T23: -101936.95 | U23: 9456967.4
B24: 2006 | C24: I TRIM | D24: 325826.78 | E24: 27386.508 | F24: 488918 | G24: 17477.84 | H24: 116223.43 | I24: 19118.433 | J24: 249185.81 | K24: 241832.39 | L24: 21361.029 | M24: 81214.974 | N24: 18126.737 | O24: 37136.016 | P24: 247422.29 | Q24: 84600.132 | R24: 125129.91 | S24: 62022.121 | T24: -19622.933 | U24: 2329559.3
C25: II TRIM | D25: 422432.23 | E25: 24263.33 | F25: 465179.31 | G25: 16971.207 | H25: 122217.09 | I25: 19403.975 | J25: 229557.38 | K25: 249714.39 | L25: 49485.663 | M25: 86446.65 | N25: 20050.023 | O25: 40590.493 | P25: 277880.68 | Q25: 85874.896 | R25: 144508.66 | S25: 67189.653 | T25: -20646.574 | U25: 2308646.6
C26: III TRIM | D26: 230446.14 | E26: 23283.688 | F26: 484892.85 | G26: 19513.612 | H26: 127080.95 | I26: 19432.075 | J26: 261484.12 | K26: 260205.74 | L26: 65859.841 | M26: 101538.82 | N26: 20745.231 | O26: 61039.736 | P26: 248724.88 | Q26: 86919.998 | R26: 146555.03 | S26: 77578.538 | T26: -22223.698 | U26: 2319490.8
C27: IV TRIM | D27: 147864.89 | E27: 39434.669 | F27: 482740.83 | G27: 18901.569 | H27: 145221.6 | I27: 22586.2 | J27: 251859.47 | K27: 275568.61 | L27: 76281.603 | M27: 102566.69 | N27: 23845.785 | O27: 89833.516 | P27: 430372 | Q27: 97020.49 | R27: 129046.43 | S27: 103868.52 | T27: -39443.749 | U27: 2499270.6
C28: Total | D28: 1188292.8 | E28: 121804.14 | F28: 2337831.4 | G28: 86786.287 | H28: 529829.98 | I28: 87553.298 | J28: 1164426.3 | K28: 1160342.9 | L28: 234975.52 | M28: 402561.61 | N28: 90649.853 | O28: 241339.61 | P28: 1321874.1 | Q28: 371975.31 | R28: 481034.17 | S28: 353397.71 | T28: -110071.52 | U28: 10686628
B29: 2007 | C29: I TRIM | D29: 351118.4 | E29: 31168.4 | F29: 595896.67 | G29: 19612.769 | H29: 122408.6 | I29: 12680.442 | J29: 291297.79 | K29: 262462.18 | L29: 25860.83 | M29: 85380.098 | N29: 20945.196 | O29: 47125.503 | P29: 290037.44 | Q29: 90627.054 | R29: 117101.96 | S29: 89191.673 | T29: -27987.468 | U29: 2658034.9
C30: II TRIM | D30: 443928.46 | E30: 26238.315 | F30: 568009.76 | G30: 16649.152 | H30: 126458.04 | I30: 25063.449 | J30: 271469.24 | K30: 279038.88 | L30: 56179.475 | M30: 91614.221 | N30: 21393.856 | O30: 51617.035 | P30: 293226.71 | Q30: 91802.363 | R30: 125239.9 | S30: 86699.158 | T30: -14516.278 | U30: 2626302.9
C31: III TRIM | D31: 239488.28 | E31: 24281.358 | F31: 587099.2 | G31: 22248.515 | H31: 130562.23 | I31: 24807.995 | J31: 308756.37 | K31: 298083.9 | L31: 71585.102 | M31: 110059.92 | N31: 21763.257 | O31: 65753.505 | P31: 317818.71 | Q31: 93581.494 | R31: 124606.47 | S31: 90215.897 | T31: -1526.1286 | U31: 2674965.8
C32: IV TRIM | D32: 153757.69 | E32: 40116.064 | F32: 586825.74 | G32: 28275.851 | H32: 150401.11 | I32: 25001.412 | J32: 292902.93 | K32: 320757.89 | L32: 81350.11 | M32: 115507.38 | N32: 26547.544 | O32: 76843.567 | P32: 420791.2 | Q32: 95964.401 | R32: 114085.85 | S32: 87290.982 | T32: -66041.647 | U32: 2727323.9
